2023-10-17 21:26:33,638 INFO    MainThread:14847 [wandb_setup.py:_flush():76] Current SDK version is 0.15.5
2023-10-17 21:26:33,638 INFO    MainThread:14847 [wandb_setup.py:_flush():76] Configure stats pid to 14847
2023-10-17 21:26:33,638 INFO    MainThread:14847 [wandb_setup.py:_flush():76] Loading settings from /home/zhizhuo/.config/wandb/settings
2023-10-17 21:26:33,638 INFO    MainThread:14847 [wandb_setup.py:_flush():76] Loading settings from /home/zhizhuo/Creative_Machines_Lab/knolling_bot/train_multi_knolling_zzz/wandb/settings
2023-10-17 21:26:33,638 INFO    MainThread:14847 [wandb_setup.py:_flush():76] Loading settings from environment variables: {}
2023-10-17 21:26:33,638 INFO    MainThread:14847 [wandb_setup.py:_flush():76] Applying setup settings: {'_disable_service': False}
2023-10-17 21:26:33,638 INFO    MainThread:14847 [wandb_setup.py:_flush():76] Inferring run settings from compute environment: {'program_relpath': 'train_multi_knolling_zzz/train_multi_knolling.py', 'program': '/home/zhizhuo/Creative_Machines_Lab/knolling_bot/train_multi_knolling_zzz/train_multi_knolling.py'}
2023-10-17 21:26:33,638 INFO    MainThread:14847 [wandb_init.py:_log_setup():507] Logging user logs to /home/zhizhuo/Creative_Machines_Lab/knolling_bot/train_multi_knolling_zzz/wandb/run-20231017_212633-oqjdmiey/logs/debug.log
2023-10-17 21:26:33,638 INFO    MainThread:14847 [wandb_init.py:_log_setup():508] Logging internal logs to /home/zhizhuo/Creative_Machines_Lab/knolling_bot/train_multi_knolling_zzz/wandb/run-20231017_212633-oqjdmiey/logs/debug-internal.log
2023-10-17 21:26:33,638 INFO    MainThread:14847 [wandb_init.py:init():547] calling init triggers
2023-10-17 21:26:33,638 INFO    MainThread:14847 [wandb_init.py:init():554] wandb.init called with sweep_config: {}
config: {}
2023-10-17 21:26:33,638 INFO    MainThread:14847 [wandb_init.py:init():596] starting backend
2023-10-17 21:26:33,639 INFO    MainThread:14847 [wandb_init.py:init():600] setting up manager
2023-10-17 21:26:33,639 INFO    MainThread:14847 [backend.py:_multiprocessing_setup():106] multiprocessing start_methods=fork,spawn,forkserver, using: spawn
2023-10-17 21:26:33,641 INFO    MainThread:14847 [wandb_init.py:init():606] backend started and connected
2023-10-17 21:26:33,641 INFO    MainThread:14847 [wandb_init.py:init():705] updated telemetry
2023-10-17 21:26:33,650 INFO    MainThread:14847 [wandb_init.py:init():738] communicating run to backend with 60.0 second timeout
2023-10-17 21:27:33,678 ERROR   MainThread:14847 [wandb_init.py:init():764] encountered error: Run initialization has timed out after 60.0 sec. 
Please refer to the documentation for additional information: https://docs.wandb.ai/guides/track/tracking-faq#initstarterror-error-communicating-with-wandb-process-
2023-10-17 21:27:33,757 ERROR   MainThread:14847 [wandb_init.py:init():1172] Run initialization has timed out after 60.0 sec. 
Please refer to the documentation for additional information: https://docs.wandb.ai/guides/track/tracking-faq#initstarterror-error-communicating-with-wandb-process-
Traceback (most recent call last):
  File "/home/zhizhuo/anaconda3/envs/knolling/lib/python3.9/site-packages/wandb/sdk/wandb_init.py", line 1154, in init
    run = wi.init()
  File "/home/zhizhuo/anaconda3/envs/knolling/lib/python3.9/site-packages/wandb/sdk/wandb_init.py", line 770, in init
    raise error
wandb.errors.CommError: Run initialization has timed out after 60.0 sec. 
Please refer to the documentation for additional information: https://docs.wandb.ai/guides/track/tracking-faq#initstarterror-error-communicating-with-wandb-process-
2023-10-17 21:27:34,555 INFO    Thread-1  :14847 [retry.py:__call__():172] Retry attempt failed:
Traceback (most recent call last):
  File "/home/zhizhuo/anaconda3/envs/knolling/lib/python3.9/site-packages/urllib3/connectionpool.py", line 466, in _make_request
    six.raise_from(e, None)
  File "<string>", line 3, in raise_from
  File "/home/zhizhuo/anaconda3/envs/knolling/lib/python3.9/site-packages/urllib3/connectionpool.py", line 461, in _make_request
    httplib_response = conn.getresponse()
  File "/home/zhizhuo/anaconda3/envs/knolling/lib/python3.9/http/client.py", line 1377, in getresponse
    response.begin()
  File "/home/zhizhuo/anaconda3/envs/knolling/lib/python3.9/http/client.py", line 320, in begin
    version, status, reason = self._read_status()
  File "/home/zhizhuo/anaconda3/envs/knolling/lib/python3.9/http/client.py", line 281, in _read_status
    line = str(self.fp.readline(_MAXLINE + 1), "iso-8859-1")
  File "/home/zhizhuo/anaconda3/envs/knolling/lib/python3.9/socket.py", line 704, in readinto
    return self._sock.recv_into(b)
  File "/home/zhizhuo/anaconda3/envs/knolling/lib/python3.9/ssl.py", line 1242, in recv_into
    return self.read(nbytes, buffer)
  File "/home/zhizhuo/anaconda3/envs/knolling/lib/python3.9/ssl.py", line 1100, in read
    return self._sslobj.read(len, buffer)
socket.timeout: The read operation timed out

During handling of the above exception, another exception occurred:

Traceback (most recent call last):
  File "/home/zhizhuo/anaconda3/envs/knolling/lib/python3.9/site-packages/requests/adapters.py", line 487, in send
    resp = conn.urlopen(
  File "/home/zhizhuo/anaconda3/envs/knolling/lib/python3.9/site-packages/urllib3/connectionpool.py", line 798, in urlopen
    retries = retries.increment(
  File "/home/zhizhuo/anaconda3/envs/knolling/lib/python3.9/site-packages/urllib3/util/retry.py", line 550, in increment
    raise six.reraise(type(error), error, _stacktrace)
  File "/home/zhizhuo/anaconda3/envs/knolling/lib/python3.9/site-packages/urllib3/packages/six.py", line 770, in reraise
    raise value
  File "/home/zhizhuo/anaconda3/envs/knolling/lib/python3.9/site-packages/urllib3/connectionpool.py", line 714, in urlopen
    httplib_response = self._make_request(
  File "/home/zhizhuo/anaconda3/envs/knolling/lib/python3.9/site-packages/urllib3/connectionpool.py", line 468, in _make_request
    self._raise_timeout(err=e, url=url, timeout_value=read_timeout)
  File "/home/zhizhuo/anaconda3/envs/knolling/lib/python3.9/site-packages/urllib3/connectionpool.py", line 357, in _raise_timeout
    raise ReadTimeoutError(
urllib3.exceptions.ReadTimeoutError: HTTPSConnectionPool(host='api.wandb.ai', port=443): Read timed out. (read timeout=10)

During handling of the above exception, another exception occurred:

Traceback (most recent call last):
  File "/home/zhizhuo/anaconda3/envs/knolling/lib/python3.9/site-packages/wandb/sdk/lib/retry.py", line 131, in __call__
    result = self._call_fn(*args, **kwargs)
  File "/home/zhizhuo/anaconda3/envs/knolling/lib/python3.9/site-packages/wandb/sdk/internal/internal_api.py", line 321, in execute
    return self.client.execute(*args, **kwargs)  # type: ignore
  File "/home/zhizhuo/anaconda3/envs/knolling/lib/python3.9/site-packages/wandb/vendor/gql-0.2.0/wandb_gql/client.py", line 52, in execute
    result = self._get_result(document, *args, **kwargs)
  File "/home/zhizhuo/anaconda3/envs/knolling/lib/python3.9/site-packages/wandb/vendor/gql-0.2.0/wandb_gql/client.py", line 60, in _get_result
    return self.transport.execute(document, *args, **kwargs)
  File "/home/zhizhuo/anaconda3/envs/knolling/lib/python3.9/site-packages/wandb/sdk/lib/gql_request.py", line 55, in execute
    request = self.session.post(self.url, **post_args)
  File "/home/zhizhuo/anaconda3/envs/knolling/lib/python3.9/site-packages/requests/sessions.py", line 635, in post
    return self.request("POST", url, data=data, json=json, **kwargs)
  File "/home/zhizhuo/anaconda3/envs/knolling/lib/python3.9/site-packages/requests/sessions.py", line 587, in request
    resp = self.send(prep, **send_kwargs)
  File "/home/zhizhuo/anaconda3/envs/knolling/lib/python3.9/site-packages/requests/sessions.py", line 701, in send
    r = adapter.send(request, **kwargs)
  File "/home/zhizhuo/anaconda3/envs/knolling/lib/python3.9/site-packages/requests/adapters.py", line 533, in send
    raise ReadTimeout(e, request=request)
requests.exceptions.ReadTimeout: HTTPSConnectionPool(host='api.wandb.ai', port=443): Read timed out. (read timeout=10)
2023-10-17 21:27:34,769 WARNING MsgRouterThr:14847 [router.py:message_loop():77] message_loop has been closed
