2023-10-17 21:26:33,641 INFO    StreamThr :14872 [internal.py:wandb_internal():86] W&B internal server running at pid: 14872, started at: 2023-10-17 21:26:33.641500
2023-10-17 21:26:33,643 DEBUG   HandlerThread:14872 [handler.py:handle_request():144] handle_request: status
2023-10-17 21:26:33,643 INFO    WriterThread:14872 [datastore.py:open_for_write():85] open: /home/zhizhuo/Creative_Machines_Lab/knolling_bot/train_multi_knolling_zzz/wandb/run-20231017_212633-oqjdmiey/run-oqjdmiey.wandb
2023-10-17 21:26:33,644 DEBUG   SenderThread:14872 [sender.py:send():369] send: header
2023-10-17 21:26:33,651 DEBUG   SenderThread:14872 [sender.py:send():369] send: run
2023-10-17 21:26:38,654 DEBUG   HandlerThread:14872 [handler.py:handle_request():144] handle_request: keepalive
2023-10-17 21:26:43,656 DEBUG   HandlerThread:14872 [handler.py:handle_request():144] handle_request: keepalive
2023-10-17 21:26:48,658 DEBUG   HandlerThread:14872 [handler.py:handle_request():144] handle_request: keepalive
2023-10-17 21:26:53,660 DEBUG   HandlerThread:14872 [handler.py:handle_request():144] handle_request: keepalive
2023-10-17 21:26:58,662 DEBUG   HandlerThread:14872 [handler.py:handle_request():144] handle_request: keepalive
2023-10-17 21:27:03,665 DEBUG   HandlerThread:14872 [handler.py:handle_request():144] handle_request: keepalive
2023-10-17 21:27:08,667 DEBUG   HandlerThread:14872 [handler.py:handle_request():144] handle_request: keepalive
2023-10-17 21:27:13,669 DEBUG   HandlerThread:14872 [handler.py:handle_request():144] handle_request: keepalive
2023-10-17 21:27:18,671 DEBUG   HandlerThread:14872 [handler.py:handle_request():144] handle_request: keepalive
2023-10-17 21:27:23,674 DEBUG   HandlerThread:14872 [handler.py:handle_request():144] handle_request: keepalive
2023-10-17 21:27:28,676 DEBUG   HandlerThread:14872 [handler.py:handle_request():144] handle_request: keepalive
2023-10-17 21:27:33,678 DEBUG   HandlerThread:14872 [handler.py:handle_request():144] handle_request: cancel
2023-10-17 21:27:33,679 DEBUG   HandlerThread:14872 [handler.py:handle_request():144] handle_request: cancel
2023-10-17 21:27:33,762 DEBUG   HandlerThread:14872 [handler.py:handle_request():144] handle_request: shutdown
2023-10-17 21:27:33,762 INFO    HandlerThread:14872 [handler.py:finish():854] shutting down handler
2023-10-17 21:27:34,679 INFO    WriterThread:14872 [datastore.py:close():298] close: /home/zhizhuo/Creative_Machines_Lab/knolling_bot/train_multi_knolling_zzz/wandb/run-20231017_212633-oqjdmiey/run-oqjdmiey.wandb
2023-10-17 21:27:34,766 INFO    SenderThread:14872 [retry.py:__call__():172] Retry attempt failed:
Traceback (most recent call last):
  File "/home/zhizhuo/anaconda3/envs/knolling/lib/python3.9/site-packages/urllib3/connectionpool.py", line 466, in _make_request
    six.raise_from(e, None)
  File "<string>", line 3, in raise_from
  File "/home/zhizhuo/anaconda3/envs/knolling/lib/python3.9/site-packages/urllib3/connectionpool.py", line 461, in _make_request
    httplib_response = conn.getresponse()
  File "/home/zhizhuo/anaconda3/envs/knolling/lib/python3.9/http/client.py", line 1377, in getresponse
    response.begin()
  File "/home/zhizhuo/anaconda3/envs/knolling/lib/python3.9/http/client.py", line 320, in begin
    version, status, reason = self._read_status()
  File "/home/zhizhuo/anaconda3/envs/knolling/lib/python3.9/http/client.py", line 281, in _read_status
    line = str(self.fp.readline(_MAXLINE + 1), "iso-8859-1")
  File "/home/zhizhuo/anaconda3/envs/knolling/lib/python3.9/socket.py", line 704, in readinto
    return self._sock.recv_into(b)
  File "/home/zhizhuo/anaconda3/envs/knolling/lib/python3.9/ssl.py", line 1242, in recv_into
    return self.read(nbytes, buffer)
  File "/home/zhizhuo/anaconda3/envs/knolling/lib/python3.9/ssl.py", line 1100, in read
    return self._sslobj.read(len, buffer)
socket.timeout: The read operation timed out

During handling of the above exception, another exception occurred:

Traceback (most recent call last):
  File "/home/zhizhuo/anaconda3/envs/knolling/lib/python3.9/site-packages/requests/adapters.py", line 487, in send
    resp = conn.urlopen(
  File "/home/zhizhuo/anaconda3/envs/knolling/lib/python3.9/site-packages/urllib3/connectionpool.py", line 798, in urlopen
    retries = retries.increment(
  File "/home/zhizhuo/anaconda3/envs/knolling/lib/python3.9/site-packages/urllib3/util/retry.py", line 550, in increment
    raise six.reraise(type(error), error, _stacktrace)
  File "/home/zhizhuo/anaconda3/envs/knolling/lib/python3.9/site-packages/urllib3/packages/six.py", line 770, in reraise
    raise value
  File "/home/zhizhuo/anaconda3/envs/knolling/lib/python3.9/site-packages/urllib3/connectionpool.py", line 714, in urlopen
    httplib_response = self._make_request(
  File "/home/zhizhuo/anaconda3/envs/knolling/lib/python3.9/site-packages/urllib3/connectionpool.py", line 468, in _make_request
    self._raise_timeout(err=e, url=url, timeout_value=read_timeout)
  File "/home/zhizhuo/anaconda3/envs/knolling/lib/python3.9/site-packages/urllib3/connectionpool.py", line 357, in _raise_timeout
    raise ReadTimeoutError(
urllib3.exceptions.ReadTimeoutError: HTTPSConnectionPool(host='api.wandb.ai', port=443): Read timed out. (read timeout=10)

During handling of the above exception, another exception occurred:

Traceback (most recent call last):
  File "/home/zhizhuo/anaconda3/envs/knolling/lib/python3.9/site-packages/wandb/sdk/lib/retry.py", line 131, in __call__
    result = self._call_fn(*args, **kwargs)
  File "/home/zhizhuo/anaconda3/envs/knolling/lib/python3.9/site-packages/wandb/sdk/internal/internal_api.py", line 321, in execute
    return self.client.execute(*args, **kwargs)  # type: ignore
  File "/home/zhizhuo/anaconda3/envs/knolling/lib/python3.9/site-packages/wandb/vendor/gql-0.2.0/wandb_gql/client.py", line 52, in execute
    result = self._get_result(document, *args, **kwargs)
  File "/home/zhizhuo/anaconda3/envs/knolling/lib/python3.9/site-packages/wandb/vendor/gql-0.2.0/wandb_gql/client.py", line 60, in _get_result
    return self.transport.execute(document, *args, **kwargs)
  File "/home/zhizhuo/anaconda3/envs/knolling/lib/python3.9/site-packages/wandb/sdk/lib/gql_request.py", line 55, in execute
    request = self.session.post(self.url, **post_args)
  File "/home/zhizhuo/anaconda3/envs/knolling/lib/python3.9/site-packages/requests/sessions.py", line 635, in post
    return self.request("POST", url, data=data, json=json, **kwargs)
  File "/home/zhizhuo/anaconda3/envs/knolling/lib/python3.9/site-packages/requests/sessions.py", line 587, in request
    resp = self.send(prep, **send_kwargs)
  File "/home/zhizhuo/anaconda3/envs/knolling/lib/python3.9/site-packages/requests/sessions.py", line 701, in send
    r = adapter.send(request, **kwargs)
  File "/home/zhizhuo/anaconda3/envs/knolling/lib/python3.9/site-packages/requests/adapters.py", line 533, in send
    raise ReadTimeout(e, request=request)
requests.exceptions.ReadTimeout: HTTPSConnectionPool(host='api.wandb.ai', port=443): Read timed out. (read timeout=10)
2023-10-17 21:27:34,768 DEBUG   SenderThread:14872 [sender.py:send():378] Record cancelled: run
2023-10-17 21:27:34,768 INFO    SenderThread:14872 [sender.py:finish():1526] shutting down sender
