2023-04-18 16:55:58,386 INFO    MainThread:28998 [wandb_setup.py:_flush():68] Configure stats pid to 28998
2023-04-18 16:55:58,387 INFO    MainThread:28998 [wandb_setup.py:_flush():68] Loading settings from /home/zhizhuo/.config/wandb/settings
2023-04-18 16:55:58,387 INFO    MainThread:28998 [wandb_setup.py:_flush():68] Loading settings from /home/zhizhuo/ultralytics-main/ultralytics/yolo/v8/pose/wandb/settings
2023-04-18 16:55:58,387 INFO    MainThread:28998 [wandb_setup.py:_flush():68] Loading settings from environment variables: {'_require_service': 'True'}
2023-04-18 16:55:58,387 INFO    MainThread:28998 [wandb_setup.py:_flush():68] Inferring run settings from compute environment: {'program_relpath': 'train.py', 'program': '/home/zhizhuo/ultralytics-main/ultralytics/yolo/v8/pose/train.py'}
2023-04-18 16:55:58,387 INFO    MainThread:28998 [wandb_init.py:_log_setup():492] Logging user logs to /home/zhizhuo/ultralytics-main/ultralytics/yolo/v8/pose/wandb/run-20230418_165558-zhazye1q/logs/debug.log
2023-04-18 16:55:58,387 INFO    MainThread:28998 [wandb_init.py:_log_setup():493] Logging internal logs to /home/zhizhuo/ultralytics-main/ultralytics/yolo/v8/pose/wandb/run-20230418_165558-zhazye1q/logs/debug-internal.log
2023-04-18 16:55:58,387 INFO    MainThread:28998 [wandb_init.py:init():532] calling init triggers
2023-04-18 16:55:58,388 INFO    MainThread:28998 [wandb_init.py:init():538] wandb.init called with sweep_config: {}
config: {'task': 'pose', 'mode': 'train', 'model': 'yolov8n-pose.yaml', 'data': '/home/zhizhuo/ultralytics-main/ultralytics/datasets/coco8-pose.yaml', 'epochs': 100, 'patience': 50, 'batch': 16, 'imgsz': 640, 'save': True, 'save_period': -1, 'cache': False, 'device': '', 'workers': 8, 'project': None, 'name': None, 'exist_ok': False, 'pretrained': False, 'optimizer': 'SGD', 'verbose': True, 'seed': 0, 'deterministic': True, 'single_cls': False, 'image_weights': False, 'rect': False, 'cos_lr': False, 'close_mosaic': 0, 'resume': False, 'amp': True, 'overlap_mask': True, 'mask_ratio': 4, 'dropout': 0.0, 'val': True, 'split': 'val', 'save_json': False, 'save_hybrid': False, 'conf': None, 'iou': 0.7, 'max_det': 300, 'half': False, 'dnn': False, 'plots': True, 'source': None, 'show': False, 'save_txt': False, 'save_conf': False, 'save_crop': False, 'show_labels': True, 'show_conf': True, 'vid_stride': 1, 'line_thickness': 3, 'visualize': False, 'augment': False, 'agnostic_nms': False, 'classes': None, 'retina_masks': False, 'boxes': True, 'format': 'torchscript', 'keras': False, 'optimize': False, 'int8': False, 'dynamic': False, 'simplify': False, 'opset': None, 'workspace': 4, 'nms': False, 'lr0': 0.01, 'lrf': 0.01, 'momentum': 0.937, 'weight_decay': 0.0005, 'warmup_epochs': 3.0, 'warmup_momentum': 0.8, 'warmup_bias_lr': 0.1, 'box': 7.5, 'cls': 0.5, 'dfl': 1.5, 'pose': 12.0, 'kobj': 1.0, 'label_smoothing': 0.0, 'nbs': 64, 'hsv_h': 0.015, 'hsv_s': 0.7, 'hsv_v': 0.4, 'degrees': 0.0, 'translate': 0.1, 'scale': 0.5, 'shear': 0.0, 'perspective': 0.0, 'flipud': 0.0, 'fliplr': 0.5, 'mosaic': 1.0, 'mixup': 0.0, 'copy_paste': 0.0, 'cfg': None, 'v5loader': False, 'tracker': 'botsort.yaml', 'save_dir': '/home/zhizhuo/ADDdisk/Create Machine Lab/YOLOv8/runs/pose/train9'}
2023-04-18 16:55:58,388 INFO    MainThread:28998 [wandb_init.py:init():588] starting backend
2023-04-18 16:55:58,388 INFO    MainThread:28998 [wandb_init.py:init():592] setting up manager
2023-04-18 16:55:58,393 INFO    MainThread:28998 [backend.py:_multiprocessing_setup():106] multiprocessing start_methods=fork,spawn,forkserver, using: spawn
2023-04-18 16:55:58,397 INFO    MainThread:28998 [wandb_init.py:init():599] backend started and connected
2023-04-18 16:55:58,400 INFO    MainThread:28998 [wandb_init.py:init():687] updated telemetry
2023-04-18 16:55:58,401 INFO    MainThread:28998 [wandb_init.py:init():727] communicating run to backend with 60.0 second timeout
2023-04-18 16:56:33,046 INFO    Thread-2  :28998 [retry.py:__call__():172] Retry attempt failed:
Traceback (most recent call last):
  File "/home/zhizhuo/anaconda3/envs/DRL/lib/python3.9/site-packages/urllib3/connectionpool.py", line 449, in _make_request
    six.raise_from(e, None)
  File "<string>", line 3, in raise_from
  File "/home/zhizhuo/anaconda3/envs/DRL/lib/python3.9/site-packages/urllib3/connectionpool.py", line 444, in _make_request
    httplib_response = conn.getresponse()
  File "/home/zhizhuo/anaconda3/envs/DRL/lib/python3.9/http/client.py", line 1377, in getresponse
    response.begin()
  File "/home/zhizhuo/anaconda3/envs/DRL/lib/python3.9/http/client.py", line 320, in begin
    version, status, reason = self._read_status()
  File "/home/zhizhuo/anaconda3/envs/DRL/lib/python3.9/http/client.py", line 281, in _read_status
    line = str(self.fp.readline(_MAXLINE + 1), "iso-8859-1")
  File "/home/zhizhuo/anaconda3/envs/DRL/lib/python3.9/socket.py", line 704, in readinto
    return self._sock.recv_into(b)
  File "/home/zhizhuo/anaconda3/envs/DRL/lib/python3.9/ssl.py", line 1242, in recv_into
    return self.read(nbytes, buffer)
  File "/home/zhizhuo/anaconda3/envs/DRL/lib/python3.9/ssl.py", line 1100, in read
    return self._sslobj.read(len, buffer)
socket.timeout: The read operation timed out

During handling of the above exception, another exception occurred:

Traceback (most recent call last):
  File "/home/zhizhuo/anaconda3/envs/DRL/lib/python3.9/site-packages/requests/adapters.py", line 489, in send
    resp = conn.urlopen(
  File "/home/zhizhuo/anaconda3/envs/DRL/lib/python3.9/site-packages/urllib3/connectionpool.py", line 787, in urlopen
    retries = retries.increment(
  File "/home/zhizhuo/anaconda3/envs/DRL/lib/python3.9/site-packages/urllib3/util/retry.py", line 550, in increment
    raise six.reraise(type(error), error, _stacktrace)
  File "/home/zhizhuo/anaconda3/envs/DRL/lib/python3.9/site-packages/urllib3/packages/six.py", line 770, in reraise
    raise value
  File "/home/zhizhuo/anaconda3/envs/DRL/lib/python3.9/site-packages/urllib3/connectionpool.py", line 703, in urlopen
    httplib_response = self._make_request(
  File "/home/zhizhuo/anaconda3/envs/DRL/lib/python3.9/site-packages/urllib3/connectionpool.py", line 451, in _make_request
    self._raise_timeout(err=e, url=url, timeout_value=read_timeout)
  File "/home/zhizhuo/anaconda3/envs/DRL/lib/python3.9/site-packages/urllib3/connectionpool.py", line 340, in _raise_timeout
    raise ReadTimeoutError(
urllib3.exceptions.ReadTimeoutError: HTTPSConnectionPool(host='api.wandb.ai', port=443): Read timed out. (read timeout=10)

During handling of the above exception, another exception occurred:

Traceback (most recent call last):
  File "/home/zhizhuo/anaconda3/envs/DRL/lib/python3.9/site-packages/wandb/sdk/lib/retry.py", line 131, in __call__
    result = self._call_fn(*args, **kwargs)
  File "/home/zhizhuo/anaconda3/envs/DRL/lib/python3.9/site-packages/wandb/sdk/internal/internal_api.py", line 242, in execute
    return self.client.execute(*args, **kwargs)  # type: ignore
  File "/home/zhizhuo/anaconda3/envs/DRL/lib/python3.9/site-packages/wandb/vendor/gql-0.2.0/wandb_gql/client.py", line 52, in execute
    result = self._get_result(document, *args, **kwargs)
  File "/home/zhizhuo/anaconda3/envs/DRL/lib/python3.9/site-packages/wandb/vendor/gql-0.2.0/wandb_gql/client.py", line 60, in _get_result
    return self.transport.execute(document, *args, **kwargs)
  File "/home/zhizhuo/anaconda3/envs/DRL/lib/python3.9/site-packages/wandb/vendor/gql-0.2.0/wandb_gql/transport/requests.py", line 38, in execute
    request = requests.post(self.url, **post_args)
  File "/home/zhizhuo/anaconda3/envs/DRL/lib/python3.9/site-packages/requests/api.py", line 115, in post
    return request("post", url, data=data, json=json, **kwargs)
  File "/home/zhizhuo/anaconda3/envs/DRL/lib/python3.9/site-packages/requests/api.py", line 59, in request
    return session.request(method=method, url=url, **kwargs)
  File "/home/zhizhuo/anaconda3/envs/DRL/lib/python3.9/site-packages/requests/sessions.py", line 587, in request
    resp = self.send(prep, **send_kwargs)
  File "/home/zhizhuo/anaconda3/envs/DRL/lib/python3.9/site-packages/requests/sessions.py", line 701, in send
    r = adapter.send(request, **kwargs)
  File "/home/zhizhuo/anaconda3/envs/DRL/lib/python3.9/site-packages/requests/adapters.py", line 578, in send
    raise ReadTimeout(e, request=request)
requests.exceptions.ReadTimeout: HTTPSConnectionPool(host='api.wandb.ai', port=443): Read timed out. (read timeout=10)
2023-04-18 16:56:58,426 ERROR   MainThread:28998 [wandb_init.py:init():741] backend process timed out, exiting...
encountered error: Error communicating with wandb process, exiting...
For more info see: https://docs.wandb.ai/library/init#init-start-error
2023-04-18 16:56:58,432 ERROR   MainThread:28998 [wandb_init.py:init():1160] error
Traceback (most recent call last):
  File "/home/zhizhuo/anaconda3/envs/DRL/lib/python3.9/site-packages/wandb/sdk/wandb_init.py", line 1133, in init
    run = wi.init()
  File "/home/zhizhuo/anaconda3/envs/DRL/lib/python3.9/site-packages/wandb/sdk/wandb_init.py", line 759, in init
    raise error
wandb.errors.CommError: Error communicating with wandb process, exiting...
For more info see: https://docs.wandb.ai/library/init#init-start-error
2023-04-18 16:57:01,440 WARNING MsgRouterThr:28998 [router.py:message_loop():77] message_loop has been closed
