2023-04-18 16:55:58,399 INFO    StreamThr :29007 [internal.py:wandb_internal():87] W&B internal server running at pid: 29007, started at: 2023-04-18 16:55:58.399420
2023-04-18 16:55:58,401 DEBUG   HandlerThread:29007 [handler.py:handle_request():144] handle_request: status
2023-04-18 16:55:58,402 INFO    WriterThread:29007 [datastore.py:open_for_write():85] open: /home/zhizhuo/ultralytics-main/ultralytics/yolo/v8/pose/wandb/run-20230418_165558-zhazye1q/run-zhazye1q.wandb
2023-04-18 16:55:58,404 DEBUG   SenderThread:29007 [sender.py:send():336] send: header
2023-04-18 16:55:58,404 DEBUG   SenderThread:29007 [sender.py:send():336] send: run
2023-04-18 16:56:03,405 DEBUG   HandlerThread:29007 [handler.py:handle_request():144] handle_request: keepalive
2023-04-18 16:56:08,407 DEBUG   HandlerThread:29007 [handler.py:handle_request():144] handle_request: keepalive
2023-04-18 16:56:13,410 DEBUG   HandlerThread:29007 [handler.py:handle_request():144] handle_request: keepalive
2023-04-18 16:56:18,411 DEBUG   HandlerThread:29007 [handler.py:handle_request():144] handle_request: keepalive
2023-04-18 16:56:23,413 DEBUG   HandlerThread:29007 [handler.py:handle_request():144] handle_request: keepalive
2023-04-18 16:56:28,414 DEBUG   HandlerThread:29007 [handler.py:handle_request():144] handle_request: keepalive
2023-04-18 16:56:33,417 DEBUG   HandlerThread:29007 [handler.py:handle_request():144] handle_request: keepalive
2023-04-18 16:56:38,419 DEBUG   HandlerThread:29007 [handler.py:handle_request():144] handle_request: keepalive
2023-04-18 16:56:43,420 DEBUG   HandlerThread:29007 [handler.py:handle_request():144] handle_request: keepalive
2023-04-18 16:56:48,070 INFO    SenderThread:29007 [retry.py:__call__():172] Retry attempt failed:
Traceback (most recent call last):
  File "/home/zhizhuo/anaconda3/envs/DRL/lib/python3.9/site-packages/urllib3/connectionpool.py", line 449, in _make_request
    six.raise_from(e, None)
  File "<string>", line 3, in raise_from
  File "/home/zhizhuo/anaconda3/envs/DRL/lib/python3.9/site-packages/urllib3/connectionpool.py", line 444, in _make_request
    httplib_response = conn.getresponse()
  File "/home/zhizhuo/anaconda3/envs/DRL/lib/python3.9/http/client.py", line 1377, in getresponse
    response.begin()
  File "/home/zhizhuo/anaconda3/envs/DRL/lib/python3.9/http/client.py", line 320, in begin
    version, status, reason = self._read_status()
  File "/home/zhizhuo/anaconda3/envs/DRL/lib/python3.9/http/client.py", line 281, in _read_status
    line = str(self.fp.readline(_MAXLINE + 1), "iso-8859-1")
  File "/home/zhizhuo/anaconda3/envs/DRL/lib/python3.9/socket.py", line 704, in readinto
    return self._sock.recv_into(b)
  File "/home/zhizhuo/anaconda3/envs/DRL/lib/python3.9/ssl.py", line 1242, in recv_into
    return self.read(nbytes, buffer)
  File "/home/zhizhuo/anaconda3/envs/DRL/lib/python3.9/ssl.py", line 1100, in read
    return self._sslobj.read(len, buffer)
socket.timeout: The read operation timed out

During handling of the above exception, another exception occurred:

Traceback (most recent call last):
  File "/home/zhizhuo/anaconda3/envs/DRL/lib/python3.9/site-packages/requests/adapters.py", line 489, in send
    resp = conn.urlopen(
  File "/home/zhizhuo/anaconda3/envs/DRL/lib/python3.9/site-packages/urllib3/connectionpool.py", line 787, in urlopen
    retries = retries.increment(
  File "/home/zhizhuo/anaconda3/envs/DRL/lib/python3.9/site-packages/urllib3/util/retry.py", line 550, in increment
    raise six.reraise(type(error), error, _stacktrace)
  File "/home/zhizhuo/anaconda3/envs/DRL/lib/python3.9/site-packages/urllib3/packages/six.py", line 770, in reraise
    raise value
  File "/home/zhizhuo/anaconda3/envs/DRL/lib/python3.9/site-packages/urllib3/connectionpool.py", line 703, in urlopen
    httplib_response = self._make_request(
  File "/home/zhizhuo/anaconda3/envs/DRL/lib/python3.9/site-packages/urllib3/connectionpool.py", line 451, in _make_request
    self._raise_timeout(err=e, url=url, timeout_value=read_timeout)
  File "/home/zhizhuo/anaconda3/envs/DRL/lib/python3.9/site-packages/urllib3/connectionpool.py", line 340, in _raise_timeout
    raise ReadTimeoutError(
urllib3.exceptions.ReadTimeoutError: HTTPSConnectionPool(host='api.wandb.ai', port=443): Read timed out. (read timeout=10)

During handling of the above exception, another exception occurred:

Traceback (most recent call last):
  File "/home/zhizhuo/anaconda3/envs/DRL/lib/python3.9/site-packages/wandb/sdk/lib/retry.py", line 131, in __call__
    result = self._call_fn(*args, **kwargs)
  File "/home/zhizhuo/anaconda3/envs/DRL/lib/python3.9/site-packages/wandb/sdk/internal/internal_api.py", line 242, in execute
    return self.client.execute(*args, **kwargs)  # type: ignore
  File "/home/zhizhuo/anaconda3/envs/DRL/lib/python3.9/site-packages/wandb/vendor/gql-0.2.0/wandb_gql/client.py", line 52, in execute
    result = self._get_result(document, *args, **kwargs)
  File "/home/zhizhuo/anaconda3/envs/DRL/lib/python3.9/site-packages/wandb/vendor/gql-0.2.0/wandb_gql/client.py", line 60, in _get_result
    return self.transport.execute(document, *args, **kwargs)
  File "/home/zhizhuo/anaconda3/envs/DRL/lib/python3.9/site-packages/wandb/vendor/gql-0.2.0/wandb_gql/transport/requests.py", line 38, in execute
    request = requests.post(self.url, **post_args)
  File "/home/zhizhuo/anaconda3/envs/DRL/lib/python3.9/site-packages/requests/api.py", line 115, in post
    return request("post", url, data=data, json=json, **kwargs)
  File "/home/zhizhuo/anaconda3/envs/DRL/lib/python3.9/site-packages/requests/api.py", line 59, in request
    return session.request(method=method, url=url, **kwargs)
  File "/home/zhizhuo/anaconda3/envs/DRL/lib/python3.9/site-packages/requests/sessions.py", line 587, in request
    resp = self.send(prep, **send_kwargs)
  File "/home/zhizhuo/anaconda3/envs/DRL/lib/python3.9/site-packages/requests/sessions.py", line 701, in send
    r = adapter.send(request, **kwargs)
  File "/home/zhizhuo/anaconda3/envs/DRL/lib/python3.9/site-packages/requests/adapters.py", line 578, in send
    raise ReadTimeout(e, request=request)
requests.exceptions.ReadTimeout: HTTPSConnectionPool(host='api.wandb.ai', port=443): Read timed out. (read timeout=10)
2023-04-18 16:56:48,422 DEBUG   HandlerThread:29007 [handler.py:handle_request():144] handle_request: keepalive
2023-04-18 16:56:53,424 DEBUG   HandlerThread:29007 [handler.py:handle_request():144] handle_request: keepalive
2023-04-18 16:56:58,426 DEBUG   HandlerThread:29007 [handler.py:handle_request():144] handle_request: cancel
2023-04-18 16:56:58,427 DEBUG   HandlerThread:29007 [handler.py:handle_request():144] handle_request: cancel
2023-04-18 16:56:58,709 ERROR   SenderThread:29007 [internal_api.py:execute():245] 409 response executing GraphQL.
2023-04-18 16:56:58,710 ERROR   SenderThread:29007 [internal_api.py:execute():246] {"errors":[{"message":"Error 1062 (23000): Duplicate entry '37555110-zhazye1q' for key 'PRIMARY'","path":["upsertBucket"]}],"data":{"upsertBucket":null}}
2023-04-18 16:56:58,711 DEBUG   SenderThread:29007 [sender.py:send():345] Record cancelled: run
2023-04-18 16:56:58,711 DEBUG   HandlerThread:29007 [handler.py:handle_request():144] handle_request: status_report
2023-04-18 16:57:00,438 DEBUG   HandlerThread:29007 [handler.py:handle_request():144] handle_request: shutdown
2023-04-18 16:57:00,439 INFO    HandlerThread:29007 [handler.py:finish():841] shutting down handler
2023-04-18 16:57:00,711 INFO    SenderThread:29007 [sender.py:finish():1493] shutting down sender
2023-04-18 16:57:00,712 INFO    WriterThread:29007 [datastore.py:close():299] close: /home/zhizhuo/ultralytics-main/ultralytics/yolo/v8/pose/wandb/run-20230418_165558-zhazye1q/run-zhazye1q.wandb
